Workbook

Sheet Cover
B4: AJ BELL PLC (AJB.L)
B6: Discounted Cash Flow Analysis, Comps table & Investment Memo
B10: Model Date: July 2026
B14: Ticker | C14: AJB.L
B15: Exchange | C15: London Stock Exchange (Main Market)
B16: Sector | C16: Financial Services — Investment Platform
B17: Financial Year End | C17: 30 September
B18: Reporting Currency | C18: GBP (£ millions)
B19: Historical Period | C19: FY22 – FY25 (audited)
B20: Forecast Period | C20: FY26E – FY30E
B21: Model Author | C21: Patrick James
B22: Last Updated | C22: 46213
B24: Sheet Navigation
B25: Assumptions | C25: Key model inputs — revenue drivers, margins, capex, tax
B26: Historicals | C26: FY22-FY25 audited financials + H1 FY26 actuals
B27: DCF Model | C27: 5-year FCF forecast, terminal value, equity bridge WACC vs terminal growth + WACC vs exit multiple tables
B28: WACC | C28: Cost of equity (CAPM), cost of debt, capital structure
B29: Comps table | C29: Comparison of multiples compared to peers
B30: Investment Memo | C30: One-page thesis, bull/bear case, valuation summary

Sheet Assumptions
A1: AJ Bell DCF — Key Assumptions
A2: Assumption | B2: FY26E | C2: FY27E | D2: FY28E | E2: FY29E | F2: FY30E | H2: Notes / Source
A3: REVENUE DRIVERS
A4: AUA Growth Rate (Platform) | B4: 0.14 | C4: 0.12 | D4: 0.11 | E4: 0.1 | F4: 0.09 | H4: Main revenue driver, rates decrease assumption as business gets larger
A5: Revenue Margin on AUA (bps) | B5: 33.2 | C5: 33 | D5: 32.8 | E5: 32.5 | F5: 32.3 | H5: Margin on AUA, assume that fees reduce due to competitive pressure
A6: Transactional Revenue (% of Rev) | B6: 0.163 | C6: 0.155 | D6: 0.15 | E6: 0.148 | F6: 0.147 | H6: Transactional rev steps down (FY25had unusually high revenue due to US Tariff volatility
A8: PROFITABILITY
A9: PBT Margin | B9: 0.43 | C9: 0.435 | D9: 0.438 | E9: 0.44 | F9: 0.442 | H9: PBT margin expands, largely fixed cost base so greater operational leverage
A10: Effective Tax Rate | B10: 0.25 | C10: 0.25 | D10: 0.25 | E10: 0.25 | F10: 0.25 | H10: UK Corp Tax 25%, assume no change
A12: FREE CASH FLOW BRIDGE
A13: D&A (% of Revenue) | B13: 0.013 | C13: 0.013 | D13: 0.012 | E13: 0.012 | F13: 0.012 | H13: FY25: £4.1m D&A / £317.8m rev = 1.3%
A14: Capex (% of Revenue) | B14: 0.008 | C14: 0.008 | D14: 0.008 | E14: 0.008 | F14: 0.008 | H14: FY25: £2.4m capex / £317.8m rev = 0.8%
A15: Change in NWC (% of Revenue) | B15: 0.01 | C15: 0.008 | D15: 0.007 | E15: 0.007 | F15: 0.006 | H15: FY25: +£8.0m NWC build, platform growth drives receivables growth
A17: TERMINAL VALUE
A18: Terminal Growth Rate (Gordon Growth) | B18: 0.025 | H18: Long-run UK nominal GDP 2.5%
A19: EV/EBITDA Exit Multiple (cross-check) | B19: 13 | H19: Average of comparable peers taken, see comps table for details
A21: EQUITY BRIDGE & SHARES
A22: Net Cash (£m) — FY25 actual | B22: 188.2 | H22: FY25 cash £188.2m, no financial debt (lease liabilities only, £12.1m)
A23: Diluted Shares Outstanding (m) | B23: 411.274 | H23: Approx. from FY25
A24: Share price (GBX) | B24: =607 -> 607 | H24: as of 10/07/2026

Sheet Historicals
A1: AJ Bell — Historical Financials (£000s unless stated)
A2: Line Item | B2: FY22 30-Sep-22 | C2: FY23 30-Sep-23 | D2: FY24 30-Sep-24 | E2: FY25 30-Sep-25 | F2: H1 FY26 31-Mar-26 | G2: FY22-25 CAGR | H2: Notes
A3: INCOME STATEMENT (£000s)
A4: Recurring Fixed Revenue | B4: 29787 | C4: 30666 | D4: 32078 | E4: 32496
A5: Recurring Ad Valorem Revenue | B5: 102184 | C5: 161152 | D5: 202040 | E5: 232384
A6: Transactional Revenue | B6: 31876 | C6: 26416 | D6: 35317 | E6: 52967
A7: Total Revenue | B7: 163800 | C7: 218200 | D7: 269435 | E7: 317847 | F7: 183000 | G7: =(E7/B7)^(1/3)-1 -> 0.24729182
A8: YoY Revenue Growth | B8: 0.12 | C8: =C7/B7-1 -> 0.33211233 | D8: =D7/C7-1 -> 0.23480752 | E8: =E7/D7-1 -> 0.1796797
A9: Administrative Expenses | B9: 104886 | C9: 132014 | D9: 162157 | E9: 185890
A10: Operating Profit | B10: 58981 | C10: 86220 | D10: 107278 | E10: 131957
A11: Investment Income | B11: 198 | C11: 2392 | D11: 6909 | E11: 6800
A12: Finance Costs | B12: 768 | C12: 952 | D12: 904 | E12: 931
A13: Profit Before Tax (PBT) | B13: 58411 | C13: 87661 | D13: 113283 | E13: 137826 | F13: 92800 | G13: =(E13/B13)^(1/3)-1 -> 0.3313089
A14: PBT Margin | B14: =B13/B7 -> 0.35659951 | C14: =C13/C7 -> 0.4017461 | D14: =D13/D7 -> 0.42044649 | E14: =E13/E7 -> 0.43362372 | H14: PBT margin increasing consistently
A15: Tax Expense | B15: 11672 | C15: 19442 | D15: 28988 | E15: 32705
A16: Profit After Tax | B16: 46739 | C16: 68219 | D16: 84295 | E16: 105121 | F16: 69160
A17: Basic EPS (pence) | B17: 11.39 | C17: 16.59 | D17: 20.46 | E17: 25.68 | F17: 17.23
A18: Diluted EPS (pence) | B18: 11.35 | C18: 16.53 | D18: 20.34 | E18: 25.56 | F18: 17.13
A19: Dividend per Share (pence) | D19: 12.5 | E19: 14.25 | F19: 5
A21: KEY OPERATIONAL METRICS
A22: Total Platform Customers (000s) | B22: 440.6 | C22: 491.4 | D22: 542 | E22: 644 | F22: 723
A23: YoY Customer Growth | B23: 0.16 | C23: =C22/B22-1 -> 0.11529732 | D23: =D22/C22-1 -> 0.1029711 | E23: =E22/D22-1 -> 0.18819188 | F23: =F22/E22-1 -> 0.12267081 | G23: =(E22/B22)^(1/3)-1 -> 0.13487264 | H23: 3 Year customer growth rate around 13%
A24: Total AUA (£bn) | B24: 69.2 | C24: 76.1 | D24: 92.2 | E24: 108.2 | F24: 110.2
A25: Platform AUA (£bn) | B25: 64.1 | C25: 70.9 | D25: 86.5 | E25: 103.3 | F25: 108.7
A26: AUM — AJ Bell Investments (£bn) | B26: 2.8 | C26: 4.7 | D26: 6.8 | E26: 8.9 | F26: 9.8
A27: Revenue Margin on AUA (bps) | B27: 22.6 | C27: 29.8 | D27: 31.6 | E27: 32.3 | F27: 33.4 | H27: Assumption that the upwards trajectory reverses from management warning that elevated FX dealing wont repeat
A28: Platform Net Inflows (£bn) | B28: 3.8 | C28: 4.1 | D28: 6.1 | E28: 7.5 | F28: 4.2
A29: Customer Retention Rate | B29: 0.955 | C29: 0.952 | D29: 0.942 | E29: 0.941 | F29: 0.946
A31: CASH FLOW SUMMARY (£000s)
A32: Operating Cash Flow (net) | B32: 45798 | C32: 101410 | D32: 96290 | E32: 86485
A33: Capital Expenditure (incl. intan) | B33: 3379 | C33: 3500 | D33: 2949 | E33: 2436
A34: Free Cash Flow (Operating - Capex) | B34: =B32-B33 -> 42419 | C34: =C32-C33 -> 97910 | D34: =D32-D33 -> 93341 | E34: =E32-E33 -> 84049 | F34: =F32+F33 -> 0
A35: D&A | B35: 3643 | C35: 4788 | D35: 3432 | E35: 4080
A36: Cash & Equivalents (year-end) | B36: 84030 | C36: 146304 | D36: 196651 | E36: 188192
A39: BALANCE SHEET HIGHLIGHTS (£000s)
A40: Total Non-Current Assets | B40: 31758 | C40: 29517 | D40: 31616 | E40: 34714
A41: Total Current Assets | B41: 133505 | C41: 204805 | D41: 257265 | E41: 266732
A42: Total Assets | B42: 165482 | C42: 234322 | D42: 288881 | E42: 303080
A43: Total Liabilities | B43: 32088 | C43: 68285 | D43: 84891 | E43: 85628
A44: Net Assets / Total Equity | B44: 133394 | C44: 166037 | D44: 203990 | E44: 217452
...

Sheet Comps Table
A1: AJ Bell PLC (AJB.L) — Comparable Company Analysis (Comps Table)
A2: Data as at: July 2026 | Currency: GBp / £m unless stated | Source: Company filings, Koyfin, Yahoo Finance | Blue shading = subject company
A4: SECTION 1 — COMPANY OVERVIEW & MARKET DATA
A5: Company | B5: Ticker | C5: Tier | D5: Share Price (GBX) | E5: Market Cap (£m) | F5: Net Cash / (Debt) £m | G5: Enterprise Value £m | H5: TTM Revenue (£m) | I5: Rev Growth YoY | J5: EBITDA / Adj. Op. Profit £m | K5: EBITDA Margin | L5: AUM / AUA (£bn) | M5: Trailing P/E | N5: Forward P/E | O5: EV / Revenue | P5: EV / EBITDA | Q5: Div Yield | R5: Notes
A6: AJ Bell plc ★ SUBJECT | B6: AJBL | C6: Subject | D6: =Assumptions!B24 -> 607 | E6: 2472 | F6: 155.5 | G6: =E6-F6 -> 2316.5 | H6: 347.6 | I6: 0.1934 | J6: 158.5 | K6: 0.456 | L6: 108.2 | M6: 20.7 | N6: 20.6x | O6: =G6/H6 -> 6.6642693 | P6: =G6/J6 -> 14.615142 | Q6: 0.0235
A7: IntegraFin Holdings | B7: IHPL | C7: Tier 1 | D7: 377.75 | E7: 1275.6 | F7: 278 | G7: =E7-F7 -> 997.6 | H7: 165 | I7: 0.0903 | J7: 130.6 | K7: 0.7896 | L7: £67.9bn | M7: 20.2 | N7: 17.8 | O7: =G7/H7 -> 6.0460606 | P7: 11.6 | Q7: 0.0306 | R7: Closest structural comp and runs Transact wrap platform. High EBITDA margin in last 12 months but generally lower multiples compared to AJBell
A8: Quilter plc | B8: QLTL | C8: Tier 1 | D8: 199.2 | E8: 2775 | F8: — | G8: 1298 | H8: 9364 | I8: 0.7185 | J8: 362 | K8: 0.0387 | L8: 141.9 | M8: 24.2x | N8: 16.5x | O8: 0.1x | P8: 3.5x | Q8: 0.0303 | R8: Mixed model company with platform, advice and asset management making it less of a comp than IHP. High revenue and revenue growth but translates into lower EBITDA margin and lower EV/EBITDA, EV/Revenue multiples
A9: St. James's Place plc | B9: STJL | C9: Tier 1 | D9: 1165.82 | E9: 6777.2 | F9: — | G9: 6889.9 | H9: 30162.4 | I9: 0.1612 | J9: 1309.6 | K9: 0.0434 | L9: £220.0bn | M9: 13.6x | N9: 17.0x | O9: 0.2x | P9: 5.2x | Q9: 0.0137 | R9: P/E distorted by ongoing advice remediation charges. The fee model used by SJP under regulatory scrutiny and differs structurally when compared to AJ Bell so use as caution as comp.
A10: Tatton Asset Management | B10: TAML | C10: Tier 2 | D10: 720 | E10: 440.6 | F10: 34 | G10: 406.1 | H10: 54.3 | I10: 0.2034 | J10: 24 | K10: 0.4425 | L10: 24.2 | M10: 24.0x | N10: 18.3x | O10: 7.5x | P10: 16.7x | Q10: 0.037 | R10: Partial comp, hence tier 2 with no D2C platform. Smaller earnings but similar multiples/
A11: Brooks Macdonald Group | B11: BRK | C11: Tier 2 | D11: 1315 | E11: 200.8 | F11: — | G11: 201.8 | H11: 117.9 | I11: 0.1201 | J11: 11.6 | K11: 0.0984 | L11: £19.9bn | M11: 29.3x | N11: 9.5x | O11: 1.7x | P11: 14.4x | Q11: 0.0631 | R11: Discretionary wealth manager so tier 2 partial comp only (no platform). Included for sector context with a smaller scale than AJB and different revenue model.
A13: SECTION 2 — PEER MULTIPLE SUMMARY (Tier 1 only — exclude STJ distorted P/E)
A14: Metric | B14: AJ Bell (Subject) | C14: IHP (Tier 1) | D14: QLT (Tier 1) | E14: STJ (Tier 1 — ⚠) | F14: Mean (ex STJ) | G14: Median (ex STJ) | H14: AJB Metric | I14: Implied price based on median | J14: Implied upside/ (downside) vs current price | K14: Note
A15: Trailing P/E | B15: =M6 -> 20.7 | C15: =M7 -> 20.2 | D15: =M8 -> 24.2x | E15: =M9 -> 13.6x | F15: =AVERAGE(B15,C15,D15) -> 20.45 | G15: =MEDIAN(B15,C15,D15) -> 20.45 | H15: ="AJBL EPS: " & Historicals!E18&"p" -> AJBL EPS: 25.56p | I15: ='Comps Table'!G15*Historicals!E18 -> 522.702 | J15: =(I15/D6)-1 -> -0.13887644 | K15: Similar P/E to peers but decreased implied price comparatively
A16: Forward P/E | B16: =N6 -> 20.6x | C16: =N7 -> 17.8 | D16: =N8 -> 16.5x | E16: =N9 -> 17.0x | F16: =AVERAGE(B16,C16,D16) -> 17.8 | G16: =MEDIAN(B16,C16,D16) -> 17.8 | H16: ="AJBL EPS: " & Historicals!E18&"p" -> AJBL EPS: 25.56p | I16: ='Comps Table'!G16*Historicals!E18 -> 454.968 | J16: =(I16/D6)-1 -> -0.25046458 | K16: Greatest forward P/E; Implied price significantly lower when compared to peers
A17: EV/Revenue | B17: =O6 -> 6.6642693 | C17: =O7 -> 6.0460606 | D17: =O8 -> 0.1x | E17: =O9 -> 0.2x | F17: =AVERAGE(B17,C17,D17) -> 6.3551649 | G17: =MEDIAN(B17,C17,D17) -> 6.3551649 | H17: ="AJBL Rev: "&H6&"m" -> AJBL Rev: 347.6m | I17: =((G17*H6)+F6)/Assumptions!B23*100 -> 574.93431 | J17: =(I17/D6)-1 -> -0.052826508 | K17: Highest EV/Revenue Multiple reflects the superior margins however average multiple of peers implies a lower price, but ignores PBT margins
A18: Rev Growth YoY | B18: =I6 -> 0.1934 | C18: =I7 -> 0.0903 | D18: =I8 -> 0.7185 | E18: =I9 -> 0.1612 | F18: =AVERAGE(B18,C18,D18) -> 0.33406667 | G18: =MEDIAN(B18,C18,D18) -> 0.1934 | H18: - | I18: - | K18: High growth but comparatively less than QLT great revenue growth in past year
A19: EV / EBITDA | B19: =P6 -> 14.615142 | C19: =P7 -> 11.6 | D19: =P8 -> 3.5x | E19: =P9 -> 5.2x | F19: =AVERAGE(B19,C19,D19) -> 13.107571 | G19: =MEDIAN(B19,C19,D19) -> 13.107571 | H19: ="AJBL EBITDA: "&J6&"m" -> AJBL EBITDA: 158.5m | I19: =((G19*J6)+F6)/Assumptions!B23*100 -> 542.9592 | J19: =(I19/D6)-1 -> -0.1055038 | K19: AJ Bell shows highest Ev / EBITDA compared to peers; again compared to peer average AJ Bell EBITDA implies a lower price
A20: EBITDA Margin | B20: =K6 -> 0.456 | C20: =K7 -> 0.7896 | D20: =K8 -> 0.0387 | E20: =K9 -> 0.0434 | F20: =AVERAGE(B20,C20,D20) -> 0.4281 | G20: =MEDIAN(B20,C20,D20) -> 0.456 | H20: - | I20: - | K20: AJB margin generally higher than average
A21: Div Yield | B21: =Q6 -> 0.0235 | C21: =Q7 -> 0.0306 | D21: =Q8 -> 0.0303 | E21: =Q9 -> 0.0137 | F21: =AVERAGE(B21,C21,D21) -> 0.028133333 | G21: =MEDIAN(B21,C21,D21) -> 0.0303 | H21: - | I21: - | K21: AJB yield in line with peers
A24: SECTION 3 — KEY ANALYTICAL OBSERVATIONS
A25: 1. AJ Bell trades at a premium
A26: AJ Bell trades at a premium on the price implied by the average of peer multiples. Based on the findings of the DCF model this appears to be justified due to AJB's superior margins and persistent growth in revenue and these margins.
A27: 2. Peer universe is thin
A28: HL, Interactive Investor and Nucleus are all private meaning that the listed UK platform universe has shrunk to IHP and QLT as pure comps. This limits the statistical robustness of any mean/median multiple.
A29: 3. St James Place is only a partial comp
A30: SJP's P/E is distorted by ongoing advice remediation charges and the 2023 fee restructuring. Its AUM scale (£185bn+) dwarfs AJB, and its advised-only model is structurally different. It is included for context but is not used to compare multiples.
A31: 4. Tatton is the highest quality growth comp but is listed on the AIM
A32: TAM has 20% revenue growth, 52% group margin, and debt-free balance sheet make it a good operational comp for AJB's trajectory. However its AIM listing, smaller scale (£54m rev vs £318m), and DFM-only model (no direct platform) limit its comparability. It can be used to help validate the margin expansion assumptions but not to compare valuation multiples.

Sheet DCF Model
A1: AJ Bell — DCF Model (£000s)
A2: Line Item | B2: FY26E | C2: FY27E | D2: FY28E | E2: FY29E | F2: FY30E | G2: FY26-30E CAGR | H2: Formula / Note
A3: REVENUE BUILD
A4: Opening Platform AUA (£bn) | B4: 103.3 | C4: =B4*(1+Assumptions!B4) -> 117.762 | D4: =C4*(1+Assumptions!C4) -> 131.89344 | E4: =D4*(1+Assumptions!D4) -> 146.40172 | F4: =E4*(1+Assumptions!E4) -> 161.04189 | H4: FY25 platform AUA closing, Historicals tab
A5: AUA Growth Rate | B5: =Assumptions!B4 -> 0.14 | C5: =Assumptions!C4 -> 0.12 | D5: =Assumptions!D4 -> 0.11 | E5: =Assumptions!E4 -> 0.1 | F5: =Assumptions!F4 -> 0.09 | H5: Pulled from Assumptions tab row 4
A6: Closing Platform AUA (£bn) | B6: =B4*(1+B5) -> 117.762 | C6: =C4*(1+C5) -> 131.89344 | D6: =D4*(1+D5) -> 146.40172 | E6: =E4*(1+E5) -> 161.04189 | F6: =F4*(1+F5) -> 175.53566
A7: Revenue Margin (bps) | B7: =Assumptions!B5 -> 33.2 | C7: =Assumptions!C5 -> 33 | D7: =Assumptions!D5 -> 32.8 | E7: =Assumptions!E5 -> 32.5 | F7: =Assumptions!F5 -> 32.3 | H7: Pulled from Assumptions tab row 5
A8: TOTAL REVENUE (£000s) | B8: =(B4+B6)/2*B7/10000*1000000 -> 366962.92 | C8: =(C4+C6)/2*C7/10000*1000000 -> 411931.48 | D8: =(D4+D6)/2*D7/10000*1000000 -> 456404.06 | E8: =(E4+E6)/2*E7/10000*1000000 -> 499595.86 | F8: =(F4+F6)/2*F7/10000*1000000 -> 543572.74 | G8: =(F8/B8)^(1/4)-1 -> 0.10321173 | H8: Avg opening+closing AUA × revenue margin, Average is used as fees are earned throughout the year
A9: Transactional revenue (£000s) | B9: =B8*Assumptions!B6 -> 59814.956 | C9: =C8*Assumptions!C6 -> 63849.379 | D9: =D8*Assumptions!D6 -> 68460.609 | E9: =E8*Assumptions!E6 -> 73940.188 | F9: =F8*Assumptions!F6 -> 79905.193
A10: Recurring Revenue (£000s) | B10: =B8-B9 -> 307147.96 | C10: =C8-C9 -> 348082.1 | D10: =D8-D9 -> 387943.45 | E10: =E8-E9 -> 425655.68 | F10: =F8-F9 -> 463667.55
A12: P&L BUILD
A13: PBT Margin | B13: =Assumptions!B9 -> 0.43 | C13: =Assumptions!C9 -> 0.435 | D13: =Assumptions!D9 -> 0.438 | E13: =Assumptions!E9 -> 0.44 | F13: =Assumptions!F9 -> 0.442 | H13: Key driver see Assumptions
A14: Profit Before Tax | B14: =B8*B13 -> 157794.06 | C14: =C8*C13 -> 179190.19 | D14: =D8*D13 -> 199904.98 | E14: =E8*E13 -> 219822.18 | F14: =F8*F13 -> 240259.15
A15: EBITDA | B15: =B14+B20 -> 162564.57 | C15: =C14+C20 -> 184545.3 | D15: =D14+D20 -> 205381.83 | E15: =E14+E20 -> 225817.33 | F15: =F14+F20 -> 246782.03 | H15: EBITDA is just PBT plus D&A again as AJ bell has very little debt and debt expense
A16: Tax Expense | B16: =-B14*Assumptions!B10 -> -39448.514 | C16: =-C14*Assumptions!C10 -> -44797.548 | D16: =-D14*Assumptions!D10 -> -49976.245 | E16: =-E14*Assumptions!E10 -> -54955.545 | F16: =-F14*Assumptions!F10 -> -60064.788
A17: NOPAT (PBT × (1-Tax)) | B17: =B14+B16 -> 118345.54 | C17: =C14+C16 -> 134392.64 | D17: =D14+D16 -> 149928.73 | E17: =E14+E16 -> 164866.64 | F17: =F14+F16 -> 180194.36 | H17: NOPAT is PBT * (1-Tax) instead of EBIT *(1- tax), finance items stripped out as AJ Bell has no debt and minimal finance costs
A19: FREE CASH FLOW BUILD (£000s)
A20: Add: D&A | B20: =B8*Assumptions!B13 -> 4770.518 | C20: =C8*Assumptions!C13 -> 5355.1092 | D20: =D8*Assumptions!D13 -> 5476.8487 | E20: =E8*Assumptions!E13 -> 5995.1504 | F20: =F8*Assumptions!F13 -> 6522.8729 | H20: D&A as % of revenue, Assumptions row 13
A21: Less: Capex | B21: =-B8*Assumptions!B14 -> -2935.7034 | C21: =-C8*Assumptions!C14 -> -3295.4518 | D21: =-D8*Assumptions!D14 -> -3651.2325 | E21: =-E8*Assumptions!E14 -> -3996.7669 | F21: =-F8*Assumptions!F14 -> -4348.582 | H21: Capex as % of revenue, Assumptions row 14
A22: Less: Change in NWC | B22: =-B8*Assumptions!B15 -> -3669.6292 | C22: =-C8*Assumptions!C15 -> -3295.4518 | D22: =-D8*Assumptions!D15 -> -3194.8284 | E22: =-E8*Assumptions!E15 -> -3497.171 | F22: =-F8*Assumptions!F15 -> -3261.4365 | H22: NWC change as % of revenue, Assumptions row 15
A23: UNLEVERED FREE CASH FLOW (UFCF) | B23: =B17+B20+B21+B22 -> 116510.73 | C23: =C17+C20+C21+C22 -> 133156.85 | D23: =D17+D20+D21+D22 -> 148559.52 | E23: =E17+E20+E21+E22 -> 163367.85 | F23: =F17+F20+F21+F22 -> 179107.22 | G23: =(F23/B23)^(1/4)-1 -> 0.11349121
A25: DISCOUNTING
A26: WACC | B26: =WACC!B19 -> 0.085935 | C26: =WACC!B19 -> 0.085935 | D26: =WACC!B19 -> 0.085935 | E26: =WACC!B19 -> 0.085935 | F26: =WACC!B19 -> 0.085935 | H26: WACC calculated in WACC tab
A27: Discount Period | B27: 0.5 | C27: 1.5 | D27: 2.5 | E27: 3.5 | F27: 4.5 | H27: cash flows treated as arriving mid year on average, mid year convention
A28: Discount Factor | B28: =1/(1+B26)^B27 -> 0.95961733 | C28: =1/(1+B26)^C27 -> 0.88367843 | D28: =1/(1+B26)^D27 -> 0.81374892 | E28: =1/(1+B26)^E27 -> 0.74935324 | F28: =1/(1+B26)^F27 -> 0.6900535
A29: PV of UFCF | B29: =B23*B28 -> 111805.71 | C29: =C23*C28 -> 117667.84 | D29: =D23*D28 -> 120890.15 | E29: =E23*E28 -> 122420.23 | F29: =F23*F28 -> 123593.56
A31: TERMINAL VALUE
A32: Terminal Growth Rate | B32: =Assumptions!B18 -> 0.025
A33: Terminal Value — Gordon Growth (£000s) | B33: =F23*(1+B32)/(B26-B32) -> 3012798.9
A34: PV of Terminal Value (£000s) | B34: =B33*F28 -> 2078992.4
A35: Exit Multiple | B35: =Assumptions!B19 -> 13
A36: Terminal value - Exit Multiple | B36: =F15*B35 -> 3208166.3
A37: PV of terminal value | B37: =B36*F28 -> 2213806.4
A38: ENTERPRISE VALUE BRIDGE (£000s) (Gordon Growth)
A39: Sum of PV FCFs | B39: =SUM(B29:F29) -> 596377.49
A40: PV of Terminal Value (Gordon Growth) | B40: =B34 -> 2078992.4
A41: ENTERPRISE VALUE (£000s) | B41: =B39+B40 -> 2675369.9
A42: Terminal Value as % of EV | B42: =B40/B41 -> 0.77708597
A43: Add: Net Cash (£000s) | B43: =Assumptions!B22*1000 -> 188200
A44: EQUITY VALUE (£000s) | B44: =B41+B43 -> 2863569.9
...

Sheet WACC
A1: AJ Bell — WACC Calculation
A3: COST OF EQUITY — CAPM
A4: Risk-Free Rate (UK 10Y Gilt yield) | B4: 0.044 | D4: UK 10Y Gilt approx. 4.4% as of Jun 2026
A5: Equity Risk Premium (UK) | B5: 0.05 | D5: standard assumption for UK equities
A6: Beta (levered) | B6: 0.86 | D6: AJB listed beta vs FTSE All-Share
A7: Cost of Equity (Ke) = Rf + β × ERP | B7: =B4+B6*B5 -> 0.087 | D7: CAPM< formula
A9: COST OF DEBT
A10: Cost of Debt (pre-tax) | B10: 0.045 | D10: AJB has no financial debt , Use risk free rate with small spread
A11: Tax Rate | B11: 0.25 | D11: UK Corp Tax 25%
A12: After-Tax Cost of Debt (Kd) | B12: =B10*(1-B11) -> 0.03375
A14: CAPITAL STRUCTURE
A15: Weight of Equity (E/V) | B15: 0.98 | D15: AJB net cash positive, no financial debt so equity 98%
A16: Weight of Debt (D/V) | B16: =1-B15 -> 0.02
A18: WACC
A19: WACC = (Ke × E/V) + (Kd × D/V) | B19: =B7*B15+B12*B16 -> 0.085935 | D19: This value flows into DCF Model tab

Sheet Investment Memo
B1: AJ BELL PLC (AJB.L) — Investment Memo
B3: THESIS
B4: AJ Bell is a buy at 607p. The market underestimates the platform's structural growth runway and operational gearing as it accesses a £2.4 trillion addressable market, implying an upside of at least 10% to our DCF-derived fair value of 696p under Gordon growth assumption methodology. (value of 729p under the exit multiple estimation methodology).
B6: BULL CASE
B7: 1. Structural growth: £2.4tn of UK Investable assets are off platform. AJ Bell's dual-channel model (advised + D2C) is the only major platform with scale in both segments simultaneously, giving two independent growth opportunities against a single fixed cost base. 2. Operational gearing: Revenue per customer has grown from £370 in FY22 to £490 approx. in FY25 as AUA per customer rises and dealing activity increases. Cost-to-serve per £AUA is falling, meaning PBT margins are expected to expand in future. 3. Capital returns: 21 consecutive years of dividend growth; £50m buyback FY26; no financial debt = all FCF available for distributions.
B9: BEAR CASE / KEY RISKS
B10: 1. Fee compression: Hargreaves Lansdown taken private partly due to competitive pressure, Vanguard or other cheapest platform could compress AJB revenue margins, these have risen from 31.6bps in FY24 to 33.4bps in H1 FY26, driven by interest income and elevated dealing activity, but these are both cyclical and a reduction in bps by 2bps reduces estimated revenue by approx. £21m and is a bear case risk that cannot be fully priced in. 2. Interest rate sensitivity: £232m ad valorem revenue partly driven by retained interest income on cash and is not separately disclosed. If BoE cuts rates to 3% this tailwind is reduced. 3. Regulatory risk: FCA Consumer Duty requires platforms to demonstrate their value for money, Aj Bells fee structure is relatively defensible but there is uncertainty. Furthermore, ISA reform complexity, and pension tax changes create compliance costs and potential customer confusion/outflows.
B12: VALUATION SUMMARY
B13: DCF Base Case: 696.3p Current Price: 607p as of 10th July Implied Upside/(Downside): 10.4% WACC: 8.6% Terminal Growth Rate: 2.5% TV as % of EV: 77%
B15: WHAT WOULD CHANGE MY MIND
B16: DOWNGRADE triggers: (1) Revenue margin falls below 30bps for 2 consecutive halves, signalling structural fee pressure. (2) Net inflows fall, signalling competitive share loss to Vanguard, interactive investor or Hargreaves Lansdown. (3) Regulatory action by FCA materially restricting ISA/SIPP product economics. (4) Cost growth outpaces revenue growth for 2 consecutive years breaking the operating leverage thesis in the bull case. UPGRADE triggers: (1) AUA growth re-accelerates above 20% for two consecutive halves as ISA reform drives accelerated platform adoption. (2) Margin expansion faster than modelled (e.g. AI-driven cost reduction). (3) M&A activity in sector at premium multiples re-rates the stock, competitive intensity reduces in D2C segment.
